Workbook
Name data: [1]Data!$A$2:$D$1637
Name peg: #REF!
Name wen: #REF!

Sheet Page 372
A1: THE EVENT STUDY TIME LINE
A2: ='ICICI Securities'!A11 -> 44713 | D2: ='ICICI Securities'!A275 -> 45100 | E2: ='ICICI Securities'!A276 -> 45103 | G2: ='ICICI Securities'!A279 -> 45107 | I2: ='ICICI Securities'!A282 -> 45112 | J2: ='ICICI Securities'!A283 -> 45113 | L2: ='ICICI Securities'!A299 -> 45135
A3: T0 | D3: T1 | E3: T1 + 1 | G3: 0 | I3: T2 | J3: T2 + 1 | L3: T3
A6: Start date for estimation window | D6: End date for estimation window | E6: Start date for event window | G6: Event date | I6: End date for event window | J6: Start date for post-event window | L6: End date for post-event window

Sheet Dataset
B1: NYSE | D1: NIFTY200 | G1: ICICI Securities | J1: ICICI Bank
A2: Date | B2: Px Last | C2: Return | D2: Px Last | E2: Return | F2: Px Volume | G2: Px Last | H2: Return | I2: Px Volume | J2: Px Last | K2: Return
A3: 44378 | B3: 4709.38 | D3: 8325.55 | F3: 1893100 | G3: 660.15 | I3: 4101600 | J3: 630.85
A4: 44379 | B4: 4638.05 | C4: =B4/B3-1 -> -0.015146367 | D4: 8307.85 | E4: =D4/D3-1 -> -0.0021259857 | F4: 3458800 | G4: 692.75 | H4: =G4/G3-1 -> 0.049382716 | I4: 3528400 | J4: 640.25 | K4: =J4/J3-1 -> 0.014900531 | M4: First Day | N4: 38168 | O4: =N4 -> 38168 | Q4: =G4/G3-1 -> 0.049382716
A5: 44382 | B5: 4673.75 | C5: =B5/B4-1 -> 0.0076972003 | D5: 8326.5 | E5: =D5/D4-1 -> 0.0022448648 | F5: 4386200 | G5: 688.9 | H5: =G5/G4-1 -> -0.0055575604 | I5: 3692300 | J5: 647.85 | K5: =J5/J4-1 -> 0.011870363 | M5: Last Day | N5: 38717 | O5: =N5 -> 38717 | Q5: =G5/G4-1 -> -0.0055575604
A6: 44383 | B6: 4626.02 | C6: =B6/B5-1 -> -0.010212356 | D6: 8382.1 | E6: =D6/D5-1 -> 0.0066774755 | F6: 4438200 | G6: 712.25 | H6: =G6/G5-1 -> 0.033894615 | I6: 3590300 | J6: 650.30 | K6: =J6/J5-1 -> 0.0037817396 | O6: =O5-O4 -> 549 | Q6: =G6/G5-1 -> 0.033894615
A7: 44384 | B7: 4645.1 | C7: =B7/B6-1 -> 0.0041244958 | D7: 8376.1 | E7: =D7/D6-1 -> -0.00071581107 | F7: 3791100 | G7: 717.2 | H7: =G7/G6-1 -> 0.0069498069 | I7: 4144200 | J7: 654.00 | K7: =J7/J6-1 -> 0.0056896817 | O7: =O6/10 -> 54.9 | Q7: =G7/G6-1 -> 0.0069498069
A8: 44385 | B8: 4529.07 | C8: =B8/B7-1 -> -0.02497901 | D8: 8411.65 | E8: =D8/D7-1 -> 0.0042442187 | F8: 3541200 | G8: 706.7 | H8: =G8/G7-1 -> -0.014640268 | I8: 2906300 | J8: 641.90 | K8: =J8/J7-1 -> -0.018501529
A9: 44386 | B9: 4499.64 | C9: =B9/B8-1 -> -0.0064980228 | D9: 8345.55 | E9: =D9/D8-1 -> -0.0078581491 | F9: 5301000 | G9: 714.95 | H9: =G9/G8-1 -> 0.011673978 | I9: 4722800 | J9: 638.55 | K9: =J9/J8-1 -> -0.0052188814
A10: 44389 | B10: 4486.7 | C10: =B10/B9-1 -> -0.0028757856 | D10: 8338.95 | E10: =D10/D9-1 -> -0.00079084063 | F10: 4514200 | G10: 701.75 | H10: =G10/G9-1 -> -0.01846283 | I10: 3990700 | J10: 646.25 | K10: =J10/J9-1 -> 0.01205857 | M10: Drop Down | N10: 45106 | O10: 0
A11: 44390 | B11: 4625.21 | C11: =B11/B10-1 -> 0.030871242 | D11: 8345.4 | E11: =D11/D10-1 -> 0.00077347868 | F11: 3170900 | G11: 690 | H11: =G11/G10-1 -> -0.016743855 | I11: 4333900 | J11: 664.95 | K11: =J11/J10-1 -> 0.02893617 | N11: 45106 | O11: 60
A12: 44391 | B12: 4641.63 | C12: =B12/B11-1 -> 0.0035501091 | D12: 8392.9 | E12: =D12/D11-1 -> 0.0056917583 | F12: 3328600 | G12: 707.05 | H12: =G12/G11-1 -> 0.024710145 | I12: 3406100 | J12: 664.35 | K12: =J12/J11-1 -> -0.00090232348
A13: 44392 | B13: 4783.95 | C13: =B13/B12-1 -> 0.030661643 | D13: 8411.75 | E13: =D13/D12-1 -> 0.002245946 | F13: 3340100 | G13: 726.55 | H13: =G13/G12-1 -> 0.027579379 | I13: 5163900 | J13: 667.45 | K13: =J13/J12-1 -> 0.0046662151 | M13: Drop Down | N13: 45740 | O13: 0
A14: 44393 | B14: 4800.16 | C14: =B14/B13-1 -> 0.0033884133 | D14: 8448.2 | E14: =D14/D13-1 -> 0.0043332244 | F14: 3047500 | G14: 764.35 | H14: =G14/G13-1 -> 0.052026702 | I14: 5550200 | J14: 660.30 | K14: =J14/J13-1 -> -0.010712413 | N14: 45740 | O14: 60
A15: 44396 | B15: 4845.37 | C15: =B15/B14-1 -> 0.0094184361 | D15: 8457.45 | E15: =D15/D14-1 -> 0.0010949078 | F15: 2929600 | G15: 774.6 | H15: =G15/G14-1 -> 0.013410087 | I15: 4643700 | J15: 655.90 | K15: =J15/J14-1 -> -0.0066636377
A16: 44397 | B16: 4856.44 | C16: =B16/B15-1 -> 0.0022846552 | D16: 8373.45 | E16: =D16/D15-1 -> -0.0099320717 | F16: 2572000 | G16: 760.15 | H16: =G16/G15-1 -> -0.01865479 | I16: 4888900 | J16: 641.90 | K16: =J16/J15-1 -> -0.021344717
A17: 44399 | B17: 4970.94 | C17: =B17/B16-1 -> 0.023576941 | D17: 8302.7 | E17: =D17/D16-1 -> -0.0084493249 | F17: 3968900 | G17: 743.8 | H17: =G17/G16-1 -> -0.021508913 | I17: 5702600 | J17: 655.95 | K17: =J17/J16-1 -> 0.021888145
A18: 44400 | B18: 4801.58 | C18: =B18/B17-1 -> -0.034070015 | D18: 8409.55 | E18: =D18/D17-1 -> 0.012869308 | F18: 2968400 | G18: 725.45 | H18: =G18/G17-1 -> -0.02467061 | I18: 3687200 | J18: 676.65 | K18: =J18/J17-1 -> 0.031557283 | N18: Table
A19: 44403 | B19: 4862.01 | C19: =B19/B18-1 -> 0.012585441 | D19: 8422.7 | E19: =D19/D18-1 -> 0.0015636984 | F19: 2690000 | G19: 713.05 | H19: =G19/G18-1 -> -0.017092839 | I19: 3682500 | J19: 676.75 | K19: =J19/J18-1 -> 0.00014778689 | N19: Date | O19: Icici securities | P19: Icici
A20: 44404 | B20: 4844.63 | C20: =B20/B19-1 -> -0.0035746533 | D20: 8411 | E20: =D20/D19-1 -> -0.0013891033 | F20: 2815300 | G20: 732 | H20: =G20/G19-1 -> 0.026575976 | I20: 3143900 | J20: 677.45 | K20: =J20/J19-1 -> 0.0010343554 | N20: 44911 | O20: 511.85 | P20: 902.00
A21: 44405 | B21: 4829.71 | C21: =B21/B20-1 -> -0.0030796986 | D21: 8368.5 | E21: =D21/D20-1 -> -0.0050529069 | F21: 2632400 | G21: 728 | H21: =G21/G20-1 -> -0.0054644809 | I21: 3402700 | J21: 685.05 | K21: =J21/J20-1 -> 0.01121854 | N21: 44980 | O21: 477.45 | P21: 839.75
A22: 44406 | B22: 4809.1 | C22: =B22/B21-1 -> -0.004267337 | D22: 8350.55 | E22: =D22/D21-1 -> -0.0021449483 | F22: 2139800 | G22: 723.85 | H22: =G22/G21-1 -> -0.0057005495 | I22: 2968900 | J22: 687.50 | K22: =J22/J21-1 -> 0.0035763813 | N22: 45042 | O22: 434.7 | P22: 914.95
A23: 44407 | B23: 4730.21 | C23: =B23/B22-1 -> -0.016404317 | D23: 8386.25 | E23: =D23/D22-1 -> 0.0042751675 | F23: 2867800 | G23: 725 | H23: =G23/G22-1 -> 0.0015887269 | I23: 5076600 | J23: 682.50 | K23: =J23/J22-1 -> -0.0072727273 | M23: Announcement | N23: 45105 | O23: 613.9 | P23: 937.45
A24: 44410 | B24: 4793.56 | C24: =B24/B23-1 -> 0.01339264 | D24: 8396.15 | E24: =D24/D23-1 -> 0.0011805038 | F24: 2664100 | G24: 744.55 | H24: =G24/G23-1 -> 0.026965517 | I24: 4318000 | J24: 681.40 | K24: =J24/J23-1 -> -0.0016117216 | N24: 45107 | O24: 608.45 | P24: 934.60
A25: 44411 | B25: 4897.97 | C25: =B25/B24-1 -> 0.021781307 | D25: 8471.15 | E25: =D25/D24-1 -> 0.0089326656 | F25: 2714500 | G25: 741.6 | H25: =G25/G24-1 -> -0.0039621248 | I25: 4695400 | J25: 690.40 | K25: =J25/J24-1 -> 0.013208101 | N25: 45161 | O25: 621.65 | P25: 966.85
A26: 44412 | B26: 4870.29 | C26: =B26/B25-1 -> -0.0056513209 | D26: 8577.5 | E26: =D26/D25-1 -> 0.012554376 | F26: 1915900 | G26: 723.4 | H26: =G26/G25-1 -> -0.024541532 | I26: 3144900 | J26: 714.65 | K26: =J26/J25-1 -> 0.035124565 | N26: 45202 | O26: 616.15 | P26: 940.30
A27: 44413 | B27: 4898.05 | C27: =B27/B26-1 -> 0.0056998659 | D27: 8606.9 | E27: =D27/D26-1 -> 0.0034275721 | F27: 2236300 | G27: 720.55 | H27: =G27/G26-1 -> -0.0039397291 | I27: 3240400 | J27: 702.45 | K27: =J27/J26-1 -> -0.017071294 | N27: 45315 | O27: 764.65 | P27: 999.20
A28: 44414 | B28: 4923.27 | C28: =B28/B27-1 -> 0.0051489879 | D28: 8618.75 | E28: =D28/D27-1 -> 0.0013768023 | F28: 3152800 | G28: 708.8 | H28: =G28/G27-1 -> -0.016306988 | I28: 3825300 | J28: 697.65 | K28: =J28/J27-1 -> -0.0068332266 | N28: 45390 | O28: 718.75 | P28: 1,087.15
A29: 44417 | B29: 4917.6 | C29: =B29/B28-1 -> -0.0011516736 | D29: 8599.45 | E29: =D29/D28-1 -> -0.0022393038 | F29: 2757500 | G29: 714.3 | H29: =G29/G28-1 -> 0.0077595937 | I29: 3045600 | J29: 702.85 | K29: =J29/J28-1 -> 0.0074535942 | N29: 45499 | O29: 767.35 | P29: 1,207.20
A30: 44418 | B30: 4870.57 | C30: =B30/B29-1 -> -0.0095636083 | D30: 8594.4 | E30: =D30/D29-1 -> -0.00058724686 | F30: 2375400 | G30: 687.15 | H30: =G30/G29-1 -> -0.03800924 | I30: 3196700 | J30: 700.90 | K30: =J30/J29-1 -> -0.0027744184 | N30: 45659 | O30: 861.9 | P30: 1,290.60
A31: 44419 | B31: 4887.41 | C31: =B31/B30-1 -> 0.0034575009 | D31: 8586.95 | E31: =D31/D30-1 -> -0.00086684353 | F31: 2797900 | G31: 693.05 | H31: =G31/G30-1 -> 0.0085861893 | I31: 3538400 | J31: 693.55 | K31: =J31/J30-1 -> -0.010486517 | M31: Merged | N31: 45740 | P31: 1,358.15
A32: 44420 | B32: 4875.63 | C32: =B32/B31-1 -> -0.0024102746 | D32: 8583.95 | E32: =D32/D31-1 -> -0.00034936735 | F32: 2174500 | G32: 707.9 | H32: =G32/G31-1 -> 0.021427025 | I32: 2516200 | J32: 701.35 | K32: =J32/J31-1 -> 0.011246485 | N32: 45744 | P32: 1,348.35
A33: 44421 | B33: 4956.28 | C33: =B33/B32-1 -> 0.016541452 | D33: 8631 | E33: =D33/D32-1 -> 0.0054811596 | F33: 1609000 | G33: 718.55 | H33: =G33/G32-1 -> 0.015044498 | I33: 2972400 | J33: 704.80 | K33: =J33/J32-1 -> 0.0049190846 | N33: 45790 | P33: 1,430.60
A34: 44424 | B34: 4995.25 | C34: =B34/B33-1 -> 0.0078627519 | D34: 8694.3 | E34: =D34/D33-1 -> 0.0073340285 | F34: 2107600 | G34: 700.5 | H34: =G34/G33-1 -> -0.025120033 | I34: 3375400 | J34: 702.65 | K34: =J34/J33-1 -> -0.0030505108 | N34: 45860 | P34: 1,473.60
A35: 44425 | B35: 4932.6 | C35: =B35/B34-1 -> -0.012541915 | D35: 8705 | E35: =D35/D34-1 -> 0.0012306914 | F35: 2778900 | G35: 712.75 | H35: =G35/G34-1 -> 0.017487509 | I35: 3106200 | J35: 701.20 | K35: =J35/J34-1 -> -0.0020636163 | N35: 45987 | P35: 1,375.00
A36: 44426 | B36: 5006.32 | C36: =B36/B35-1 -> 0.014945465 | D36: 8734.6 | E36: =D36/D35-1 -> 0.0034003446 | F36: 3888100 | G36: 717.9 | H36: =G36/G35-1 -> 0.0072255349 | I36: 3576600 | J36: 688.30 | K36: =J36/J35-1 -> -0.018397034
A37: 44428 | B37: 5004.98 | C37: =B37/B36-1 -> -0.00026766168 | D37: 8725.8 | E37: =D37/D36-1 -> -0.0010074875 | F37: 2612500 | G37: 683.4 | H37: =G37/G36-1 -> -0.048056832 | I37: 2440900 | J37: 680.70 | K37: =J37/J36-1 -> -0.011041697
A38: 44431 | B38: 5101.81 | C38: =B38/B37-1 -> 0.019346731 | D38: 8641.6 | E38: =D38/D37-1 -> -0.009649545 | F38: 4022600 | G38: 668.55 | H38: =G38/G37-1 -> -0.021729587 | I38: 3782400 | J38: 682.70 | K38: =J38/J37-1 -> 0.0029381519
A39: 44432 | B39: 5135.12 | C39: =B39/B38-1 -> 0.0065290554 | D39: 8646.45 | E39: =D39/D38-1 -> 0.00056123866 | F39: 2561200 | G39: 687.3 | H39: =G39/G38-1 -> 0.028045771 | I39: 2976000 | J39: 694.45 | K39: =J39/J38-1 -> 0.017211074
A40: 44433 | B40: 5085.3 | C40: =B40/B39-1 -> -0.0097018181 | D40: 8722.95 | E40: =D40/D39-1 -> 0.0088475617 | F40: 4724600 | G40: 692.2 | H40: =G40/G39-1 -> 0.0071293467 | I40: 3185800 | J40: 691.05 | K40: =J40/J39-1 -> -0.0048959608
...

Sheet ICICI Securities
A1: ICICI Securities RETURNS: THE SIGNIFICANCE OF THE ABNORMAL RETURNS
A2: Intercept | B2: =INTERCEPT($C$11:$C$275,$B$11:$B$275) -> 0.00096391056 | D2: T test Hypothesis
A3: Slope | B3: =SLOPE($C$11:$C$275,$B$11:$B$275) -> 0.11973327
A4: R-squared | B4: =RSQ($C$11:$C$275,$B$11:$B$275) -> 0.0028311552 | D4: H0: abnormal return = 0
A5: Steyx | B5: =STEYX($C$11:$C$275,$B$11:$B$275) -> 0.017498714 | D5: H1: abnormal return =! 0
A7: Days in estimation window | B7: 265
D9: EVENT WINDOW
A10: Date | B10: Nifty200 | C10: ICICI Securities | D10: Abnormal return (AR) | E10: AR t-test | F10: AR signicant? | G10: Cumulative abnormal return
A11: =Dataset!A230 -> 44713 | B11: =Dataset!E230 -> -0.0038101856 | C11: =Dataset!H230 -> -0.01409396
A12: =Dataset!A231 -> 44714 | B12: =Dataset!E231 -> -0.0039962724 | C12: =Dataset!H231 -> 0.0085091899
A13: =Dataset!A232 -> 44715 | B13: =Dataset!E232 -> 0.0064001745 | C13: =Dataset!H232 -> 0.036112049
A14: =Dataset!A233 -> 44718 | B14: =Dataset!E233 -> -0.0060058519 | C14: =Dataset!H233 -> -0.0092290988
A15: =Dataset!A234 -> 44719 | B15: =Dataset!E234 -> -0.0011992472 | C15: =Dataset!H234 -> -0.0025205479
A16: =Dataset!A235 -> 44720 | B16: =Dataset!E235 -> -0.0087035452 | C16: =Dataset!H235 -> 0.01658976
A17: =Dataset!A236 -> 44721 | B17: =Dataset!E236 -> -0.0037090268 | C17: =Dataset!H236 -> 0.00054036529
A18: =Dataset!A237 -> 44722 | B18: =Dataset!E237 -> 0.0071780911 | C18: =Dataset!H237 -> -0.0073449989
A19: =Dataset!A238 -> 44725 | B19: =Dataset!E238 -> -0.014808312 | C19: =Dataset!H238 -> -0.038737758
A20: =Dataset!A239 -> 44726 | B20: =Dataset!E239 -> -0.025987502 | C20: =Dataset!H239 -> 0.0096219153
A21: =Dataset!A240 -> 44727 | B21: =Dataset!E240 -> -0.001968113 | C21: =Dataset!H240 -> 0.019845274
A22: =Dataset!A241 -> 44728 | B22: =Dataset!E241 -> -0.0011940515 | C22: =Dataset!H241 -> -0.037598945
... A275: =Dataset!A494 -> 45100 | B275: =Dataset!E494 -> -0.0062906322 | C275: =Dataset!H494 -> 0.070437262
A276: =Dataset!A495 -> 45103 | B276: =Dataset!E495 -> -0.0075612364 | C276: =Dataset!H495 -> 0.10452002 | D276: =C276-($B$2+$B$3*B276) -> 0.10446145 | E276: =D276/$B$5 -> 5.9696642 | F276: =IF(ABS(E276)<1.96,"no","yes") -> yes | G276: =D276 -> 0.10446145
A277: =Dataset!A496 -> 45104 | B277: =Dataset!E496 -> 0.002993662 | C277: =Dataset!H496 -> -0.026933591 | D277: =C277-($B$2+$B$3*B277) -> -0.028255942 | E277: =D277/$B$5 -> -1.6147439 | F277: =IF(ABS(E277)<1.96,"no","yes") -> no | G277: =G276+D277 -> 0.076205504
A278: =Dataset!A497 -> 45105 | B278: =Dataset!E497 -> 0.0061721513 | C278: =Dataset!H497 -> 0.014459225 | D278: =C278-($B$2+$B$3*B278) -> 0.012756303 | E278: =D278/$B$5 -> 0.72898514 | F278: =IF(ABS(E278)<1.96,"no","yes") -> no | G278: =G277+D278 -> 0.088961806
A279: =Dataset!A498 -> 45107 | B279: =Dataset!E498 -> 0.007766071 | C279: =Dataset!H498 -> -0.0088776674 | D279: =C279-($B$2+$B$3*B279) -> -0.010771435 | E279: =D279/$B$5 -> -0.61555581 | F279: =IF(ABS(E279)<1.96,"no","yes") -> no | G279: =G278+D279 -> 0.078190371
A280: =Dataset!A499 -> 45110 | B280: =Dataset!E499 -> 0.0099401293 | C280: =Dataset!H499 -> -0.0012326403 | D280: =C280-($B$2+$B$3*B280) -> -0.0033867151 | E280: =D280/$B$5 -> -0.1935408 | F280: =IF(ABS(E280)<1.96,"no","yes") -> no | G280: =G279+D280 -> 0.074803656
A281: =Dataset!A500 -> 45111 | B281: =Dataset!E500 -> 0.005942985 | C281: =Dataset!H500 -> -0.0019746585 | D281: =C281-($B$2+$B$3*B281) -> -0.0036501421 | E281: =D281/$B$5 -> -0.20859488 | F281: =IF(ABS(E281)<1.96,"no","yes") -> no | G281: =G280+D281 -> 0.071153514
A282: =Dataset!A501 -> 45112 | B282: =Dataset!E501 -> 0.0018102397 | C282: =Dataset!H501 -> 0.0023907667 | D282: =C282-($B$2+$B$3*B282) -> 0.0012101102 | E282: =D282/$B$5 -> 0.069154237 | F282: =IF(ABS(E282)<1.96,"no","yes") -> no | G282: =G281+D282 -> 0.072363624
A283: =Dataset!A502 -> 45113 | B283: =Dataset!E502 -> 0.0022096084 | C283: =Dataset!H502 -> 0.0014803849
A284: =Dataset!A503 -> 45114 | B284: =Dataset!E503 -> 0.0057715109 | C284: =Dataset!H503 -> -0.011332841
A285: =Dataset!A504 -> 45117 | B285: =Dataset!E504 -> -0.008388379 | C285: =Dataset!H504 -> 0.013622394
A286: =Dataset!A505 -> 45118 | B286: =Dataset!E505 -> -0.00026527544 | C286: =Dataset!H505 -> -0.0018028354
A287: =Dataset!A506 -> 45119 | B287: =Dataset!E506 -> 0.0054199344 | C287: =Dataset!H506 -> 0.0017239964
A288: =Dataset!A507 -> 45120 | B288: =Dataset!E507 -> -0.0011680701 | C288: =Dataset!H507 -> -0.0021307982
A289: =Dataset!A508 -> 45121 | B289: =Dataset!E508 -> -0.00063609496 | C289: =Dataset!H508 -> 0.0063239159
A290: =Dataset!A509 -> 45124 | B290: =Dataset!E509 -> 0.0082500171 | C290: =Dataset!H509 -> 0.005141598
A291: =Dataset!A510 -> 45125 | B291: =Dataset!E510 -> 0.0062109388 | C291: =Dataset!H510 -> 0.007145177
A292: =Dataset!A511 -> 45126 | B292: =Dataset!E511 -> 0.00073839561 | C292: =Dataset!H511 -> -0.0035472428
A293: =Dataset!A512 -> 45127 | B293: =Dataset!E512 -> 0.0046682324 | C293: =Dataset!H512 -> 0.022249191
A294: =Dataset!A513 -> 45128 | B294: =Dataset!E513 -> 0.0056449716 | C294: =Dataset!H513 -> 0.0019786308
...

Sheet ICICI Bank
A1: ICICI Bank RETURNS: ESTIMATION WINDOW AND EVENT WINDOW
A2: Intercept | B2: =INTERCEPT($C$11:$C$275,$B$11:$B$275) -> 0.00078651748
A3: Slope | B3: =SLOPE($C$11:$C$275,$B$11:$B$275) -> 0.10446402
A4: R-squared | B4: =RSQ($C$11:$C$275,$B$11:$B$275) -> 0.0049582584
A5: Steyx | B5: =STEYX($C$11:$C$275,$B$11:$B$275) -> 0.011524221
A7: Days in estimation window | B7: 265
D9: EVENT WINDOW
A10: Date | B10: Nifty200 | C10: ICICI Bank | D10: Abnormal return (AR) | E10: AR t-test | F10: AR signicant? | G10: Cumulative abnormal return
A11: =Dataset!A230 -> 44713 | B11: =Dataset!E230 -> -0.0038101856 | C11: =Dataset!K230 -> -0.00026565717
A12: =Dataset!A231 -> 44714 | B12: =Dataset!E231 -> -0.0039962724 | C12: =Dataset!K231 -> -0.0038530525
A13: =Dataset!A232 -> 44715 | B13: =Dataset!E232 -> 0.0064001745 | C13: =Dataset!K232 -> -0.0072690897
A14: =Dataset!A233 -> 44718 | B14: =Dataset!E233 -> -0.0060058519 | C14: =Dataset!K233 -> 0.0032916835
A15: =Dataset!A234 -> 44719 | B15: =Dataset!E234 -> -0.0011992472 | C15: =Dataset!K234 -> -0.015400067
A16: =Dataset!A235 -> 44720 | B16: =Dataset!E235 -> -0.0087035452 | C16: =Dataset!K235 -> -0.0078204692
A17: =Dataset!A236 -> 44721 | B17: =Dataset!E236 -> -0.0037090268 | C17: =Dataset!K236 -> 0.0044551062
A18: =Dataset!A237 -> 44722 | B18: =Dataset!E237 -> 0.0071780911 | C18: =Dataset!K237 -> -0.017400205
A19: =Dataset!A238 -> 44725 | B19: =Dataset!E238 -> -0.014808312 | C19: =Dataset!K238 -> -0.044444444
A20: =Dataset!A239 -> 44726 | B20: =Dataset!E239 -> -0.025987502 | C20: =Dataset!K239 -> -0.0036337209
A21: =Dataset!A240 -> 44727 | B21: =Dataset!E240 -> -0.001968113 | C21: =Dataset!K240 -> 0.0025528811
A22: =Dataset!A241 -> 44728 | B22: =Dataset!E241 -> -0.0011940515 | C22: =Dataset!K241 -> -0.012731903
... A273: =Dataset!A492 -> 45098 | B273: =Dataset!E492 -> 0.0035203099 | C273: =Dataset!K492 -> -0.00091837286
A274: =Dataset!A493 -> 45099 | B274: =Dataset!E493 -> 0.0026485606 | C274: =Dataset!K493 -> 0.0011355034 | M274: Column for x-axis on graph
A275: =Dataset!A494 -> 45100 | B275: =Dataset!E494 -> -0.0062906322 | C275: =Dataset!K494 -> -0.0024304618
A276: =Dataset!A495 -> 45103 | B276: =Dataset!E495 -> -0.0075612364 | C276: =Dataset!K495 -> 0.0042772063 | D276: =C276-($B$2+$B$3*B276) -> 0.0042805659 | E276: =D276/$B$5 -> 0.37144082 | F276: =IF(ABS(E276)<1.96,"no","yes") -> no | G276: =D276 -> 0.0042805659 | H276: =getformula(G276) -> #NAME? | M276: =TEXT(A276,"dd-mmm") -> 26-Jun
A277: =Dataset!A496 -> 45104 | B277: =Dataset!E496 -> 0.002993662 | C277: =Dataset!K496 -> 0.0093266483 | D277: =C277-($B$2+$B$3*B277) -> 0.0082274009 | E277: =D277/$B$5 -> 0.71392255 | F277: =IF(ABS(E277)<1.96,"no","yes") -> no | G277: =G276+D277 -> 0.012507967 | H277: =getformula(G277) -> #NAME? | M277: =TEXT(A277,"dd-mmm") -> 27-Jun
A278: =Dataset!A497 -> 45105 | B278: =Dataset!E497 -> 0.0061721513 | C278: =Dataset!K497 -> 0.0014421536 | D278: =C278-($B$2+$B$3*B278) -> 1.0868416e-05 | E278: =D278/$B$5 -> 0.00094309338 | F278: =IF(ABS(E278)<1.96,"no","yes") -> no | G278: =G277+D278 -> 0.012518835 | H278: =getformula(G278) -> #NAME? | M278: =TEXT(A278,"dd-mmm") -> 28-Jun
A279: =Dataset!A498 -> 45107 | B279: =Dataset!E498 -> 0.007766071 | C279: =Dataset!K498 -> -0.0030401621 | D279: =C279-($B$2+$B$3*B279) -> -0.0046379546 | E279: =D279/$B$5 -> -0.40245278 | F279: =IF(ABS(E279)<1.96,"no","yes") -> no | G279: =G278+D279 -> 0.0078808807 | M279: =TEXT(A279,"dd-mmm") -> 30-Jun
A280: =Dataset!A499 -> 45110 | B280: =Dataset!E499 -> 0.0099401293 | C280: =Dataset!K499 -> 0.0085063129 | D280: =C280-($B$2+$B$3*B280) -> 0.0066814095 | E280: =D280/$B$5 -> 0.57977106 | F280: =IF(ABS(E280)<1.96,"no","yes") -> no | G280: =G279+D280 -> 0.01456229 | M280: =TEXT(A280,"dd-mmm") -> 03-Jul
A281: =Dataset!A500 -> 45111 | B281: =Dataset!E500 -> 0.005942985 | C281: =Dataset!K500 -> 0.0022810461 | D281: =C281-($B$2+$B$3*B281) -> 0.00087370054 | E281: =D281/$B$5 -> 0.075814285 | F281: =IF(ABS(E281)<1.96,"no","yes") -> no | G281: =G280+D281 -> 0.015435991 | M281: =TEXT(A281,"dd-mmm") -> 04-Jul
A282: =Dataset!A501 -> 45112 | B282: =Dataset!E501 -> 0.0018102397 | C282: =Dataset!K501 -> 0.014078543 | D282: =C282-($B$2+$B$3*B282) -> 0.013102921 | E282: =D282/$B$5 -> 1.1369898 | F282: =IF(ABS(E282)<1.96,"no","yes") -> no | G282: =G281+D282 -> 0.028538912 | M282: =TEXT(A282,"dd-mmm") -> 05-Jul
A283: =Dataset!A502 -> 45113 | B283: =Dataset!E502 -> 0.0022096084 | C283: =Dataset!K502 -> 0.0014613779
A284: =Dataset!A503 -> 45114 | B284: =Dataset!E503 -> 0.0057715109 | C284: =Dataset!K503 -> -0.013550136
A285: =Dataset!A504 -> 45117 | B285: =Dataset!E504 -> -0.008388379 | C285: =Dataset!K504 -> 0.0021132713
A286: =Dataset!A505 -> 45118 | B286: =Dataset!E505 -> -0.00026527544 | C286: =Dataset!K505 -> -0.0036377056
A287: =Dataset!A506 -> 45119 | B287: =Dataset!E506 -> 0.0054199344 | C287: =Dataset!K506 -> -0.00058204138
A288: =Dataset!A507 -> 45120 | B288: =Dataset!E507 -> -0.0011680701 | C288: =Dataset!K507 -> 0.011965269
A289: =Dataset!A508 -> 45121 | B289: =Dataset!E508 -> -0.00063609496 | C289: =Dataset!K508 -> 0.0045516375
A290: =Dataset!A509 -> 45124 | B290: =Dataset!E509 -> 0.0082500171 | C290: =Dataset!K509 -> 0.0090099474
A291: =Dataset!A510 -> 45125 | B291: =Dataset!E510 -> 0.0062109388 | C291: =Dataset!K510 -> 0.0069681016
A292: =Dataset!A511 -> 45126 | B292: =Dataset!E511 -> 0.00073839561 | C292: =Dataset!K511 -> -0.0020503357
...

Sheet Combined
A1: ICICI Securities Merged in ICICI Bank Measuring the synergies in event window
B2: Shares outstanding (thousands) | C2: Share price, 23 June 23 | D2: Market value, 23 June 2023 (million $)
A3: ICICI Securities Measuring the synergies in event window | B3: 323100 | C3: =Dataset!G494 -> 563.05 | D3: =B3*C3/1000 -> 181921.45
A4: ICICI Bank | B4: 6957400 | C4: =Dataset!J494 -> 923.50 | D4: =B4*C4/1000 -> 6425158.9
A10: Date | B10: Abnormal returns (AR) | F10: Cumulative abnormal valuations (million $)
B11: ICICI Securities | C11: ICICI Bank | D11: Sum | F11: ICICI Securities | G11: ICICI Bank | H11: Sum
A12: ='ICICI Securities'!A276 -> 45103 | B12: ='ICICI Securities'!D276 -> 0.10446145 | C12: ='ICICI Bank'!D276 -> 0.0042805659 | D12: =B12+C12 -> 0.10874201 | F12: =$D$3*SUM($B$12:B12)/1000 -> 19.003778 | G12: =$D$4*SUM($C$12:C12)/1000 -> 27.503316 | H12: =F12+G12 -> 46.507095 | I12: =getformula(H12) -> #NAME?
A13: ='ICICI Securities'!A277 -> 45104 | B13: ='ICICI Securities'!D277 -> -0.028255942 | C13: ='ICICI Bank'!D277 -> 0.0082274009 | D13: =B13+C13 -> -0.020028541 | F13: =$D$3*SUM($B$12:B13)/1000 -> 13.863416 | G13: =$D$4*SUM($C$12:C13)/1000 -> 80.365674 | H13: =F13+G13 -> 94.229091
A14: ='ICICI Securities'!A278 -> 45105 | B14: ='ICICI Securities'!D278 -> 0.012756303 | C14: ='ICICI Bank'!D278 -> 1.0868416e-05 | D14: =B14+C14 -> 0.012767171 | F14: =$D$3*SUM($B$12:B14)/1000 -> 16.184061 | G14: =$D$4*SUM($C$12:C14)/1000 -> 80.435506 | H14: =F14+G14 -> 96.619567
A15: ='ICICI Securities'!A279 -> 45107 | B15: ='ICICI Securities'!D279 -> -0.010771435 | C15: ='ICICI Bank'!D279 -> -0.0046379546 | D15: =B15+C15 -> -0.01540939 | F15: =$D$3*SUM($B$12:B15)/1000 -> 14.224506 | G15: =$D$4*SUM($C$12:C15)/1000 -> 50.63591 | H15: =F15+G15 -> 64.860417
A16: ='ICICI Securities'!A280 -> 45110 | B16: ='ICICI Securities'!D280 -> -0.0033867151 | C16: ='ICICI Bank'!D280 -> 0.0066814095 | D16: =B16+C16 -> 0.0032946945 | F16: =$D$3*SUM($B$12:B16)/1000 -> 13.60839 | G16: =$D$4*SUM($C$12:C16)/1000 -> 93.565028 | H16: =F16+G16 -> 107.17342
A17: ='ICICI Securities'!A281 -> 45111 | B17: ='ICICI Securities'!D281 -> -0.0036501421 | C17: ='ICICI Bank'!D281 -> 0.00087370054 | D17: =B17+C17 -> -0.0027764416 | F17: =$D$3*SUM($B$12:B17)/1000 -> 12.944351 | G17: =$D$4*SUM($C$12:C17)/1000 -> 99.178693 | H17: =F17+G17 -> 112.12304
A18: ='ICICI Securities'!A282 -> 45112 | B18: ='ICICI Securities'!D282 -> 0.0012101102 | C18: ='ICICI Bank'!D282 -> 0.013102921 | D18: =B18+C18 -> 0.014313031 | F18: =$D$3*SUM($B$12:B18)/1000 -> 13.164496 | G18: =$D$4*SUM($C$12:C18)/1000 -> 183.36704 | H18: =F18+G18 -> 196.53154

Sheet Sheet1
A2: Date | B2: ICICI Bank | C2: ICICI Securities
A3: 44378 | B3: 630.85 | C3: 660.15 | L3: Drop Down | M3: 45106 | N3: 0
A4: 44379 | B4: 640.25 | C4: 692.75 | M4: 45106 | N4: 800
A5: 44382 | B5: 647.85 | C5: 688.9
A6: 44383 | B6: 650.3 | C6: 712.25 | L6: Drop Down | M6: 45740 | N6: 0
A7: 44384 | B7: 654 | C7: 717.2 | M7: 45740 | N7: 800
A8: 44385 | B8: 641.9 | C8: 706.7
A9: 44386 | B9: 638.55 | C9: 714.95
A10: 44389 | B10: 646.25 | C10: 701.75
A11: 44390 | B11: 664.95 | C11: 690
A12: 44391 | B12: 664.35 | C12: 707.05
A13: 44392 | B13: 667.45 | C13: 726.55
A14: 44393 | B14: 660.3 | C14: 764.35
A15: 44396 | B15: 655.9 | C15: 774.6
A16: 44397 | B16: 641.9 | C16: 760.15
A17: 44399 | B17: 655.95 | C17: 743.8
A18: 44400 | B18: 676.65 | C18: 725.45
A19: 44403 | B19: 676.75 | C19: 713.05
... A928: 45737 | B928: 1343.1 | C928: 896.2
A929: 45740 | B929: 1358.15
A930: 45741 | B930: 1343.7
A931: 45742 | B931: 1335.9
A932: 45743 | B932: 1336.65
A933: 45744 | B933: 1348.35
A934: 45748 | B934: 1318.45
A935: 45749 | B935: 1331.25
A936: 45750 | B936: 1329.55
A937: 45751 | B937: 1335.3
A938: 45754 | B938: 1287.55
A939: 45755 | B939: 1299.9
A940: 45756 | B940: 1300.8
... A1098: 45989 | B1098: 1388.8
